<?xml version="1.0"?>
<robot xmlns:xacro="http://ros.org/wiki/xacro" name="rover">

  <!-- Base link -->
  <link name="base_link">
    <visual>
      <geometry>
        <box size="0.4 0.3 0.2"/>
      </geometry>
      <origin xyz="0 0 0" rpy="0 0 0"/>
      <material name="gray">
        <color rgba="0.5 0.5 0.5 1.0"/>
      </material>
    </visual>
    <inertial>
      <mass value="5.0"/>
      <origin xyz="0 0 0" rpy="0 0 0"/>
      <inertia ixx="0.1" ixy="0.0" ixz="0.0" iyy="0.1" iyz="0.0" izz="0.1"/>
    </inertial>
  </link>

  <!-- Wheel macro -->
  <xacro:macro name="wheel" params="prefix x">
    <link name="${prefix}_wheel">
      <visual>
        <geometry>
          <cylinder radius="0.05" length="0.02"/>
        </geometry>
        <origin xyz="0 0 0" rpy="0 0 0"/>
      </visual>
      <inertial>
        <mass value="0.1"/>
        <origin xyz="0 0 0" rpy="0 0 0"/>
        <inertia ixx="0.0001" ixy="0.0" ixz="0.0"
                 iyy="0.0001" iyz="0.0"
                 izz="0.0001"/>
      </inertial>
    </link>

    <joint name="${prefix}_joint" type="continuous">
      <origin xyz="${x} -0.15 0" rpy="0 0 0"/>
      <parent link="base_link"/>
      <child link="${prefix}_wheel"/>
      <axis xyz="0 1 0"/>
    </joint>
  </xacro:macro>

  <!-- Instantiate wheels -->
  <xacro:wheel prefix="left" x="-0.15"/>
  <xacro:wheel prefix="right" x="0.15"/>

  <!-- Camera link -->
  <link name="camera_link">
    <visual>
      <geometry>
        <box size="0.1 0.1 0.1"/>
      </geometry>
      <origin xyz="0 0 0.2" rpy="0 0 0"/>
      <material name="blue">
        <color rgba="0.2 0.2 0.8 1.0"/>
      </material>
    </visual>
    <inertial>
      <mass value="0.05"/>
      <origin xyz="0 0 0" rpy="0 0 0"/>
      <inertia ixx="0.00005" ixy="0.0" ixz="0.0"
               iyy="0.00005" iyz="0.0"
               izz="0.00005"/>
    </inertial>
  </link>

  <joint name="camera_joint" type="fixed">
    <parent link="base_link"/>
    <child link="camera_link"/>
    <origin xyz="0 0 0.2" rpy="0 0 0"/>
  </joint>

  <!-- Transmissions -->
  <transmission name="left_trans">
    <type>transmission_interface/SimpleTransmission</type>
    <joint name="left_joint">
      <hardwareInterface>hardware_interface/EffortJointInterface</hardwareInterface>
    </joint>
    <actuator name="left_motor">
      <hardwareInterface>hardware_interface/EffortJointInterface</hardwareInterface>
      <mechanicalReduction>1</mechanicalReduction>
    </actuator>
  </transmission>

  <transmission name="right_trans">
    <type>transmission_interface/SimpleTransmission</type>
    <joint name="right_joint">
      <hardwareInterface>hardware_interface/EffortJointInterface</hardwareInterface>
    </joint>
    <actuator name="right_motor">
      <hardwareInterface>hardware_interface/EffortJointInterface</hardwareInterface>
      <mechanicalReduction>1</mechanicalReduction>
    </actuator>
  </transmission>

  <!-- Gazebo plugins -->
  <gazebo>
    <plugin name="gazebo_ros_control" filename="libgazebo_ros_control.so"/>
  </gazebo>

  <gazebo reference="base_link">
    <plugin name="gazebo_ros_diff_drive" filename="libgazebo_ros_diff_drive.so">
      <ros>
        <namespace>/</namespace>
        <remapping>cmd_vel:=/cmd_vel</remapping>
      </ros>
      <leftJoint>left_joint</leftJoint>
      <rightJoint>right_joint</rightJoint>
      <wheelSeparation>0.3</wheelSeparation>
      <wheelDiameter>0.1</wheelDiameter>
      <torque>5.0</torque>
      <commandTopic>cmd_vel</commandTopic>
      <odometryTopic>odom</odometryTopic>
      <odometryFrame>odom</odometryFrame>
      <robotBaseFrame>base_link</robotBaseFrame>
      <publishWheelTF>true</publishWheelTF>
      <publishTf>true</publishTf>
      <legacyMode>false</legacyMode>
    </plugin>
  </gazebo>

  <gazebo reference="camera_link">
    <sensor type="camera" name="camera_sensor">
      <always_on>true</always_on>
      <update_rate>30.0</update_rate>
      <camera>
        <horizontal_fov>1.3962634</horizontal_fov>
        <image>
          <width>640</width>
          <height>480</height>
          <format>R8G8B8</format>
        </image>
        <clip>
          <near>0.1</near>
          <far>100</far>
        </clip>
      </camera>
    </sensor>

    <plugin name="gazebo_ros_camera" filename="libgazebo_ros_camera.so">
      <cameraName>camera</cameraName>
      <imageTopicName>image_raw</imageTopicName>
      <cameraInfoTopicName>camera_info</cameraInfoTopicName>
      <frameName>camera_link</frameName>
      <updateRate>30.0</updateRate>
    </plugin>
  </gazebo>

</robot>

